Workbook

Sheet README
A1: Rank changes: 2018 JAMA paper (data mostly 2013–2016) vs 2026 update (data mostly 2023–2025)
A2: How to read
A3: • Rank convention is the paper's: rank 1 = HIGHEST value in the row, whether high is good or bad.
A4: • Rank change = 2018 rank − 2026 rank. Positive (▲) = the country moved toward the top (its value is now higher RELATIVE to the others); negative (▼) = moved down.
A5: • To keep the comparison fair, ranks are recomputed among only the countries that have a comparable value in BOTH years (column 'n compared'). The ranks printed in the figures are shown alongside for reference.
A6: • Performance change = rank change × desirable direction (Directions sheet): +1 if higher is better (e.g. life expectancy), −1 if lower is better (e.g. infant mortality), 0 if the indicator is descriptive (spending, utilization, workforce). Positive = the country now does BETTER relative to the other countries; negative = WORSE.
A7: • This is relative standing only: a country can improve in absolute terms yet fall in rank if others improved faster.
A8: Sheets
A9: Country_Summary — per country: how many comparable indicators improved, worsened or did not move in relative terms, overall and by domain; with chart.
A10: Performance_Matrix — indicator × country grid of performance change (green better, red worse) for indicators with a desirable direction.
A11: Rank_Movement_Matrix — indicator × country grid of raw rank change for ALL indicators (blue up, orange down), including descriptive ones.
A12: Rank_Changes — the underlying table (one row per indicator × country), with values, ranks, and comparability notes. All ranks and changes are live formulas.
... A17: Indicators with no 2026 data (drug prices, NCEs, health-system views, etc.) cannot be compared and show as excluded.

Sheet Country_Summary
A1: Relative performance by country, 2018 paper vs 2026 update
A2: Counts of comparable indicators with a desirable direction where the country's rank (among countries with data in both years) improved, worsened or did not change.
A4: Country | B4: Indicators compared | C4: Better | D4: Worse | E4: No change | F4: Net (better − worse) | G4: Share better | H4: Mean positions gained
A5: US | B5: =COUNTIFS(Rank_Changes!$E$2:$E$1090,"USA",Rank_Changes!$S$2:$S$1090,"Better")+COUNTIFS(Rank_Changes!$E$2:$E$1090,"USA",Rank_Changes!$S$2:$S$1090,"Worse")+COUNTIFS(Rank_Changes!$E$2:$E$1090,"USA",Rank_Changes!$S$2:$S$1090,"No change") -> 30 | C5: =COUNTIFS(Rank_Changes!$E$2:$E$1090,"USA",Rank_Changes!$S$2:$S$1090,"Better") -> 8 | D5: =COUNTIFS(Rank_Changes!$E$2:$E$1090,"USA",Rank_Changes!$S$2:$S$1090,"Worse") -> 6 | E5: =COUNTIFS(Rank_Changes!$E$2:$E$1090,"USA",Rank_Changes!$S$2:$S$1090,"No change") -> 16 | F5: =C5-D5 -> 2 | G5: =IF(B5=0,"",C5/B5) -> 0.26666667 | H5: =IFERROR(AVERAGEIFS(Rank_Changes!$R$2:$R$1090,Rank_Changes!$E$2:$E$1090,"USA",Rank_Changes!$Q$2:$Q$1090,"<>0",Rank_Changes!$L$2:$L$1090,1),"") -> 0.26666667
A6: UK | B6: =COUNTIFS(Rank_Changes!$E$2:$E$1090,"GBR",Rank_Changes!$S$2:$S$1090,"Better")+COUNTIFS(Rank_Changes!$E$2:$E$1090,"GBR",Rank_Changes!$S$2:$S$1090,"Worse")+COUNTIFS(Rank_Changes!$E$2:$E$1090,"GBR",Rank_Changes!$S$2:$S$1090,"No change") -> 31 | C6: =COUNTIFS(Rank_Changes!$E$2:$E$1090,"GBR",Rank_Changes!$S$2:$S$1090,"Better") -> 7 | D6: =COUNTIFS(Rank_Changes!$E$2:$E$1090,"GBR",Rank_Changes!$S$2:$S$1090,"Worse") -> 15 | E6: =COUNTIFS(Rank_Changes!$E$2:$E$1090,"GBR",Rank_Changes!$S$2:$S$1090,"No change") -> 9 | F6: =C6-D6 -> -8 | G6: =IF(B6=0,"",C6/B6) -> 0.22580645 | H6: =IFERROR(AVERAGEIFS(Rank_Changes!$R$2:$R$1090,Rank_Changes!$E$2:$E$1090,"GBR",Rank_Changes!$Q$2:$Q$1090,"<>0",Rank_Changes!$L$2:$L$1090,1),"") -> -0.74193548
A7: Germany | B7: =COUNTIFS(Rank_Changes!$E$2:$E$1090,"DEU",Rank_Changes!$S$2:$S$1090,"Better")+COUNTIFS(Rank_Changes!$E$2:$E$1090,"DEU",Rank_Changes!$S$2:$S$1090,"Worse")+COUNTIFS(Rank_Changes!$E$2:$E$1090,"DEU",Rank_Changes!$S$2:$S$1090,"No change") -> 30 | C7: =COUNTIFS(Rank_Changes!$E$2:$E$1090,"DEU",Rank_Changes!$S$2:$S$1090,"Better") -> 9 | D7: =COUNTIFS(Rank_Changes!$E$2:$E$1090,"DEU",Rank_Changes!$S$2:$S$1090,"Worse") -> 14 | E7: =COUNTIFS(Rank_Changes!$E$2:$E$1090,"DEU",Rank_Changes!$S$2:$S$1090,"No change") -> 7 | F7: =C7-D7 -> -5 | G7: =IF(B7=0,"",C7/B7) -> 0.3 | H7: =IFERROR(AVERAGEIFS(Rank_Changes!$R$2:$R$1090,Rank_Changes!$E$2:$E$1090,"DEU",Rank_Changes!$Q$2:$Q$1090,"<>0",Rank_Changes!$L$2:$L$1090,1),"") -> -0.16666667
A8: Sweden | B8: =COUNTIFS(Rank_Changes!$E$2:$E$1090,"SWE",Rank_Changes!$S$2:$S$1090,"Better")+COUNTIFS(Rank_Changes!$E$2:$E$1090,"SWE",Rank_Changes!$S$2:$S$1090,"Worse")+COUNTIFS(Rank_Changes!$E$2:$E$1090,"SWE",Rank_Changes!$S$2:$S$1090,"No change") -> 30 | C8: =COUNTIFS(Rank_Changes!$E$2:$E$1090,"SWE",Rank_Changes!$S$2:$S$1090,"Better") -> 16 | D8: =COUNTIFS(Rank_Changes!$E$2:$E$1090,"SWE",Rank_Changes!$S$2:$S$1090,"Worse") -> 7 | E8: =COUNTIFS(Rank_Changes!$E$2:$E$1090,"SWE",Rank_Changes!$S$2:$S$1090,"No change") -> 7 | F8: =C8-D8 -> 9 | G8: =IF(B8=0,"",C8/B8) -> 0.53333333 | H8: =IFERROR(AVERAGEIFS(Rank_Changes!$R$2:$R$1090,Rank_Changes!$E$2:$E$1090,"SWE",Rank_Changes!$Q$2:$Q$1090,"<>0",Rank_Changes!$L$2:$L$1090,1),"") -> 0.9
A9: France | B9: =COUNTIFS(Rank_Changes!$E$2:$E$1090,"FRA",Rank_Changes!$S$2:$S$1090,"Better")+COUNTIFS(Rank_Changes!$E$2:$E$1090,"FRA",Rank_Changes!$S$2:$S$1090,"Worse")+COUNTIFS(Rank_Changes!$E$2:$E$1090,"FRA",Rank_Changes!$S$2:$S$1090,"No change") -> 29 | C9: =COUNTIFS(Rank_Changes!$E$2:$E$1090,"FRA",Rank_Changes!$S$2:$S$1090,"Better") -> 9 | D9: =COUNTIFS(Rank_Changes!$E$2:$E$1090,"FRA",Rank_Changes!$S$2:$S$1090,"Worse") -> 11 | E9: =COUNTIFS(Rank_Changes!$E$2:$E$1090,"FRA",Rank_Changes!$S$2:$S$1090,"No change") -> 9 | F9: =C9-D9 -> -2 | G9: =IF(B9=0,"",C9/B9) -> 0.31034483 | H9: =IFERROR(AVERAGEIFS(Rank_Changes!$R$2:$R$1090,Rank_Changes!$E$2:$E$1090,"FRA",Rank_Changes!$Q$2:$Q$1090,"<>0",Rank_Changes!$L$2:$L$1090,1),"") -> -0.20689655
A10: NLD | B10: =COUNTIFS(Rank_Changes!$E$2:$E$1090,"NLD",Rank_Changes!$S$2:$S$1090,"Better")+COUNTIFS(Rank_Changes!$E$2:$E$1090,"NLD",Rank_Changes!$S$2:$S$1090,"Worse")+COUNTIFS(Rank_Changes!$E$2:$E$1090,"NLD",Rank_Changes!$S$2:$S$1090,"No change") -> 28 | C10: =COUNTIFS(Rank_Changes!$E$2:$E$1090,"NLD",Rank_Changes!$S$2:$S$1090,"Better") -> 11 | D10: =COUNTIFS(Rank_Changes!$E$2:$E$1090,"NLD",Rank_Changes!$S$2:$S$1090,"Worse") -> 12 | E10: =COUNTIFS(Rank_Changes!$E$2:$E$1090,"NLD",Rank_Changes!$S$2:$S$1090,"No change") -> 5 | F10: =C10-D10 -> -1 | G10: =IF(B10=0,"",C10/B10) -> 0.39285714 | H10: =IFERROR(AVERAGEIFS(Rank_Changes!$R$2:$R$1090,Rank_Changes!$E$2:$E$1090,"NLD",Rank_Changes!$Q$2:$Q$1090,"<>0",Rank_Changes!$L$2:$L$1090,1),"") -> -0.35714286
A11: CHE | B11: =COUNTIFS(Rank_Changes!$E$2:$E$1090,"CHE",Rank_Changes!$S$2:$S$1090,"Better")+COUNTIFS(Rank_Changes!$E$2:$E$1090,"CHE",Rank_Changes!$S$2:$S$1090,"Worse")+COUNTIFS(Rank_Changes!$E$2:$E$1090,"CHE",Rank_Changes!$S$2:$S$1090,"No change") -> 27 | C11: =COUNTIFS(Rank_Changes!$E$2:$E$1090,"CHE",Rank_Changes!$S$2:$S$1090,"Better") -> 11 | D11: =COUNTIFS(Rank_Changes!$E$2:$E$1090,"CHE",Rank_Changes!$S$2:$S$1090,"Worse") -> 7 | E11: =COUNTIFS(Rank_Changes!$E$2:$E$1090,"CHE",Rank_Changes!$S$2:$S$1090,"No change") -> 9 | F11: =C11-D11 -> 4 | G11: =IF(B11=0,"",C11/B11) -> 0.40740741 | H11: =IFERROR(AVERAGEIFS(Rank_Changes!$R$2:$R$1090,Rank_Changes!$E$2:$E$1090,"CHE",Rank_Changes!$Q$2:$Q$1090,"<>0",Rank_Changes!$L$2:$L$1090,1),"") -> 0.14814815
A12: Denmark | B12: =COUNTIFS(Rank_Changes!$E$2:$E$1090,"DNK",Rank_Changes!$S$2:$S$1090,"Better")+COUNTIFS(Rank_Changes!$E$2:$E$1090,"DNK",Rank_Changes!$S$2:$S$1090,"Worse")+COUNTIFS(Rank_Changes!$E$2:$E$1090,"DNK",Rank_Changes!$S$2:$S$1090,"No change") -> 22 | C12: =COUNTIFS(Rank_Changes!$E$2:$E$1090,"DNK",Rank_Changes!$S$2:$S$1090,"Better") -> 9 | D12: =COUNTIFS(Rank_Changes!$E$2:$E$1090,"DNK",Rank_Changes!$S$2:$S$1090,"Worse") -> 7 | E12: =COUNTIFS(Rank_Changes!$E$2:$E$1090,"DNK",Rank_Changes!$S$2:$S$1090,"No change") -> 6 | F12: =C12-D12 -> 2 | G12: =IF(B12=0,"",C12/B12) -> 0.40909091 | H12: =IFERROR(AVERAGEIFS(Rank_Changes!$R$2:$R$1090,Rank_Changes!$E$2:$E$1090,"DNK",Rank_Changes!$Q$2:$Q$1090,"<>0",Rank_Changes!$L$2:$L$1090,1),"") -> 0.77272727
A13: Canada | B13: =COUNTIFS(Rank_Changes!$E$2:$E$1090,"CAN",Rank_Changes!$S$2:$S$1090,"Better")+COUNTIFS(Rank_Changes!$E$2:$E$1090,"CAN",Rank_Changes!$S$2:$S$1090,"Worse")+COUNTIFS(Rank_Changes!$E$2:$E$1090,"CAN",Rank_Changes!$S$2:$S$1090,"No change") -> 31 | C13: =COUNTIFS(Rank_Changes!$E$2:$E$1090,"CAN",Rank_Changes!$S$2:$S$1090,"Better") -> 7 | D13: =COUNTIFS(Rank_Changes!$E$2:$E$1090,"CAN",Rank_Changes!$S$2:$S$1090,"Worse") -> 10 | E13: =COUNTIFS(Rank_Changes!$E$2:$E$1090,"CAN",Rank_Changes!$S$2:$S$1090,"No change") -> 14 | F13: =C13-D13 -> -3 | G13: =IF(B13=0,"",C13/B13) -> 0.22580645 | H13: =IFERROR(AVERAGEIFS(Rank_Changes!$R$2:$R$1090,Rank_Changes!$E$2:$E$1090,"CAN",Rank_Changes!$Q$2:$Q$1090,"<>0",Rank_Changes!$L$2:$L$1090,1),"") -> -0.25806452
A14: Japan | B14: =COUNTIFS(Rank_Changes!$E$2:$E$1090,"JPN",Rank_Changes!$S$2:$S$1090,"Better")+COUNTIFS(Rank_Changes!$E$2:$E$1090,"JPN",Rank_Changes!$S$2:$S$1090,"Worse")+COUNTIFS(Rank_Changes!$E$2:$E$1090,"JPN",Rank_Changes!$S$2:$S$1090,"No change") -> 17 | C14: =COUNTIFS(Rank_Changes!$E$2:$E$1090,"JPN",Rank_Changes!$S$2:$S$1090,"Better") -> 4 | D14: =COUNTIFS(Rank_Changes!$E$2:$E$1090,"JPN",Rank_Changes!$S$2:$S$1090,"Worse") -> 3 | E14: =COUNTIFS(Rank_Changes!$E$2:$E$1090,"JPN",Rank_Changes!$S$2:$S$1090,"No change") -> 10 | F14: =C14-D14 -> 1 | G14: =IF(B14=0,"",C14/B14) -> 0.23529412 | H14: =IFERROR(AVERAGEIFS(Rank_Changes!$R$2:$R$1090,Rank_Changes!$E$2:$E$1090,"JPN",Rank_Changes!$Q$2:$Q$1090,"<>0",Rank_Changes!$L$2:$L$1090,1),"") -> 0.058823529
A15: Australia | B15: =COUNTIFS(Rank_Changes!$E$2:$E$1090,"AUS",Rank_Changes!$S$2:$S$1090,"Better")+COUNTIFS(Rank_Changes!$E$2:$E$1090,"AUS",Rank_Changes!$S$2:$S$1090,"Worse")+COUNTIFS(Rank_Changes!$E$2:$E$1090,"AUS",Rank_Changes!$S$2:$S$1090,"No change") -> 30 | C15: =COUNTIFS(Rank_Changes!$E$2:$E$1090,"AUS",Rank_Changes!$S$2:$S$1090,"Better") -> 7 | D15: =COUNTIFS(Rank_Changes!$E$2:$E$1090,"AUS",Rank_Changes!$S$2:$S$1090,"Worse") -> 12 | E15: =COUNTIFS(Rank_Changes!$E$2:$E$1090,"AUS",Rank_Changes!$S$2:$S$1090,"No change") -> 11 | F15: =C15-D15 -> -5 | G15: =IF(B15=0,"",C15/B15) -> 0.23333333 | H15: =IFERROR(AVERAGEIFS(Rank_Changes!$R$2:$R$1090,Rank_Changes!$E$2:$E$1090,"AUS",Rank_Changes!$Q$2:$Q$1090,"<>0",Rank_Changes!$L$2:$L$1090,1),"") -> -0.3
A17: Net (better − worse) by domain
A18: Country | B18: Population health | C18: Access & quality | D18: Equity | E18: Spending | F18: Pharmaceuticals
A19: US | B19: =COUNTIFS(Rank_Changes!$E$2:$E$1090,"USA",Rank_Changes!$A$2:$A$1090,4,Rank_Changes!$S$2:$S$1090,"Better")-COUNTIFS(Rank_Changes!$E$2:$E$1090,"USA",Rank_Changes!$A$2:$A$1090,4,Rank_Changes!$S$2:$S$1090,"Worse") -> 0 | C19: =COUNTIFS(Rank_Changes!$E$2:$E$1090,"USA",Rank_Changes!$A$2:$A$1090,10,Rank_Changes!$S$2:$S$1090,"Better")-COUNTIFS(Rank_Changes!$E$2:$E$1090,"USA",Rank_Changes!$A$2:$A$1090,10,Rank_Changes!$S$2:$S$1090,"Worse") -> 0 | D19: =COUNTIFS(Rank_Changes!$E$2:$E$1090,"USA",Rank_Changes!$A$2:$A$1090,11,Rank_Changes!$S$2:$S$1090,"Better")-COUNTIFS(Rank_Changes!$E$2:$E$1090,"USA",Rank_Changes!$A$2:$A$1090,11,Rank_Changes!$S$2:$S$1090,"Worse") -> 2 | E19: =COUNTIFS(Rank_Changes!$E$2:$E$1090,"USA",Rank_Changes!$A$2:$A$1090,1,Rank_Changes!$S$2:$S$1090,"Better")-COUNTIFS(Rank_Changes!$E$2:$E$1090,"USA",Rank_Changes!$A$2:$A$1090,1,Rank_Changes!$S$2:$S$1090,"Worse") -> 0 | F19: =COUNTIFS(Rank_Changes!$E$2:$E$1090,"USA",Rank_Changes!$A$2:$A$1090,9,Rank_Changes!$S$2:$S$1090,"Better")-COUNTIFS(Rank_Changes!$E$2:$E$1090,"USA",Rank_Changes!$A$2:$A$1090,9,Rank_Changes!$S$2:$S$1090,"Worse") -> 0
A20: UK | B20: =COUNTIFS(Rank_Changes!$E$2:$E$1090,"GBR",Rank_Changes!$A$2:$A$1090,4,Rank_Changes!$S$2:$S$1090,"Better")-COUNTIFS(Rank_Changes!$E$2:$E$1090,"GBR",Rank_Changes!$A$2:$A$1090,4,Rank_Changes!$S$2:$S$1090,"Worse") -> -1 | C20: =COUNTIFS(Rank_Changes!$E$2:$E$1090,"GBR",Rank_Changes!$A$2:$A$1090,10,Rank_Changes!$S$2:$S$1090,"Better")-COUNTIFS(Rank_Changes!$E$2:$E$1090,"GBR",Rank_Changes!$A$2:$A$1090,10,Rank_Changes!$S$2:$S$1090,"Worse") -> -3 | D20: =COUNTIFS(Rank_Changes!$E$2:$E$1090,"GBR",Rank_Changes!$A$2:$A$1090,11,Rank_Changes!$S$2:$S$1090,"Better")-COUNTIFS(Rank_Changes!$E$2:$E$1090,"GBR",Rank_Changes!$A$2:$A$1090,11,Rank_Changes!$S$2:$S$1090,"Worse") -> -3 | E20: =COUNTIFS(Rank_Changes!$E$2:$E$1090,"GBR",Rank_Changes!$A$2:$A$1090,1,Rank_Changes!$S$2:$S$1090,"Better")-COUNTIFS(Rank_Changes!$E$2:$E$1090,"GBR",Rank_Changes!$A$2:$A$1090,1,Rank_Changes!$S$2:$S$1090,"Worse") -> 0 | F20: =COUNTIFS(Rank_Changes!$E$2:$E$1090,"GBR",Rank_Changes!$A$2:$A$1090,9,Rank_Changes!$S$2:$S$1090,"Better")-COUNTIFS(Rank_Changes!$E$2:$E$1090,"GBR",Rank_Changes!$A$2:$A$1090,9,Rank_Changes!$S$2:$S$1090,"Worse") -> -1
A21: Germany | B21: =COUNTIFS(Rank_Changes!$E$2:$E$1090,"DEU",Rank_Changes!$A$2:$A$1090,4,Rank_Changes!$S$2:$S$1090,"Better")-COUNTIFS(Rank_Changes!$E$2:$E$1090,"DEU",Rank_Changes!$A$2:$A$1090,4,Rank_Changes!$S$2:$S$1090,"Worse") -> -1 | C21: =COUNTIFS(Rank_Changes!$E$2:$E$1090,"DEU",Rank_Changes!$A$2:$A$1090,10,Rank_Changes!$S$2:$S$1090,"Better")-COUNTIFS(Rank_Changes!$E$2:$E$1090,"DEU",Rank_Changes!$A$2:$A$1090,10,Rank_Changes!$S$2:$S$1090,"Worse") -> -2 | D21: =COUNTIFS(Rank_Changes!$E$2:$E$1090,"DEU",Rank_Changes!$A$2:$A$1090,11,Rank_Changes!$S$2:$S$1090,"Better")-COUNTIFS(Rank_Changes!$E$2:$E$1090,"DEU",Rank_Changes!$A$2:$A$1090,11,Rank_Changes!$S$2:$S$1090,"Worse") -> -1 | E21: =COUNTIFS(Rank_Changes!$E$2:$E$1090,"DEU",Rank_Changes!$A$2:$A$1090,1,Rank_Changes!$S$2:$S$1090,"Better")-COUNTIFS(Rank_Changes!$E$2:$E$1090,"DEU",Rank_Changes!$A$2:$A$1090,1,Rank_Changes!$S$2:$S$1090,"Worse") -> 0 | F21: =COUNTIFS(Rank_Changes!$E$2:$E$1090,"DEU",Rank_Changes!$A$2:$A$1090,9,Rank_Changes!$S$2:$S$1090,"Better")-COUNTIFS(Rank_Changes!$E$2:$E$1090,"DEU",Rank_Changes!$A$2:$A$1090,9,Rank_Changes!$S$2:$S$1090,"Worse") -> -1
A22: Sweden | B22: =COUNTIFS(Rank_Changes!$E$2:$E$1090,"SWE",Rank_Changes!$A$2:$A$1090,4,Rank_Changes!$S$2:$S$1090,"Better")-COUNTIFS(Rank_Changes!$E$2:$E$1090,"SWE",Rank_Changes!$A$2:$A$1090,4,Rank_Changes!$S$2:$S$1090,"Worse") -> 1 | C22: =COUNTIFS(Rank_Changes!$E$2:$E$1090,"SWE",Rank_Changes!$A$2:$A$1090,10,Rank_Changes!$S$2:$S$1090,"Better")-COUNTIFS(Rank_Changes!$E$2:$E$1090,"SWE",Rank_Changes!$A$2:$A$1090,10,Rank_Changes!$S$2:$S$1090,"Worse") -> 7 | D22: =COUNTIFS(Rank_Changes!$E$2:$E$1090,"SWE",Rank_Changes!$A$2:$A$1090,11,Rank_Changes!$S$2:$S$1090,"Better")-COUNTIFS(Rank_Changes!$E$2:$E$1090,"SWE",Rank_Changes!$A$2:$A$1090,11,Rank_Changes!$S$2:$S$1090,"Worse") -> 0 | E22: =COUNTIFS(Rank_Changes!$E$2:$E$1090,"SWE",Rank_Changes!$A$2:$A$1090,1,Rank_Changes!$S$2:$S$1090,"Better")-COUNTIFS(Rank_Changes!$E$2:$E$1090,"SWE",Rank_Changes!$A$2:$A$1090,1,Rank_Changes!$S$2:$S$1090,"Worse") -> 1 | F22: =COUNTIFS(Rank_Changes!$E$2:$E$1090,"SWE",Rank_Changes!$A$2:$A$1090,9,Rank_Changes!$S$2:$S$1090,"Better")-COUNTIFS(Rank_Changes!$E$2:$E$1090,"SWE",Rank_Changes!$A$2:$A$1090,9,Rank_Changes!$S$2:$S$1090,"Worse") -> 0
A23: France | B23: =COUNTIFS(Rank_Changes!$E$2:$E$1090,"FRA",Rank_Changes!$A$2:$A$1090,4,Rank_Changes!$S$2:$S$1090,"Better")-COUNTIFS(Rank_Changes!$E$2:$E$1090,"FRA",Rank_Changes!$A$2:$A$1090,4,Rank_Changes!$S$2:$S$1090,"Worse") -> -1 | C23: =COUNTIFS(Rank_Changes!$E$2:$E$1090,"FRA",Rank_Changes!$A$2:$A$1090,10,Rank_Changes!$S$2:$S$1090,"Better")-COUNTIFS(Rank_Changes!$E$2:$E$1090,"FRA",Rank_Changes!$A$2:$A$1090,10,Rank_Changes!$S$2:$S$1090,"Worse") -> -6 | D23: =COUNTIFS(Rank_Changes!$E$2:$E$1090,"FRA",Rank_Changes!$A$2:$A$1090,11,Rank_Changes!$S$2:$S$1090,"Better")-COUNTIFS(Rank_Changes!$E$2:$E$1090,"FRA",Rank_Changes!$A$2:$A$1090,11,Rank_Changes!$S$2:$S$1090,"Worse") -> 5 | E23: =COUNTIFS(Rank_Changes!$E$2:$E$1090,"FRA",Rank_Changes!$A$2:$A$1090,1,Rank_Changes!$S$2:$S$1090,"Better")-COUNTIFS(Rank_Changes!$E$2:$E$1090,"FRA",Rank_Changes!$A$2:$A$1090,1,Rank_Changes!$S$2:$S$1090,"Worse") -> 0 | F23: =COUNTIFS(Rank_Changes!$E$2:$E$1090,"FRA",Rank_Changes!$A$2:$A$1090,9,Rank_Changes!$S$2:$S$1090,"Better")-COUNTIFS(Rank_Changes!$E$2:$E$1090,"FRA",Rank_Changes!$A$2:$A$1090,9,Rank_Changes!$S$2:$S$1090,"Worse") -> 0
A24: NLD | B24: =COUNTIFS(Rank_Changes!$E$2:$E$1090,"NLD",Rank_Changes!$A$2:$A$1090,4,Rank_Changes!$S$2:$S$1090,"Better")-COUNTIFS(Rank_Changes!$E$2:$E$1090,"NLD",Rank_Changes!$A$2:$A$1090,4,Rank_Changes!$S$2:$S$1090,"Worse") -> -3 | C24: =COUNTIFS(Rank_Changes!$E$2:$E$1090,"NLD",Rank_Changes!$A$2:$A$1090,10,Rank_Changes!$S$2:$S$1090,"Better")-COUNTIFS(Rank_Changes!$E$2:$E$1090,"NLD",Rank_Changes!$A$2:$A$1090,10,Rank_Changes!$S$2:$S$1090,"Worse") -> 1 | D24: =COUNTIFS(Rank_Changes!$E$2:$E$1090,"NLD",Rank_Changes!$A$2:$A$1090,11,Rank_Changes!$S$2:$S$1090,"Better")-COUNTIFS(Rank_Changes!$E$2:$E$1090,"NLD",Rank_Changes!$A$2:$A$1090,11,Rank_Changes!$S$2:$S$1090,"Worse") -> 1 | E24: =COUNTIFS(Rank_Changes!$E$2:$E$1090,"NLD",Rank_Changes!$A$2:$A$1090,1,Rank_Changes!$S$2:$S$1090,"Better")-COUNTIFS(Rank_Changes!$E$2:$E$1090,"NLD",Rank_Changes!$A$2:$A$1090,1,Rank_Changes!$S$2:$S$1090,"Worse") -> 0 | F24: =COUNTIFS(Rank_Changes!$E$2:$E$1090,"NLD",Rank_Changes!$A$2:$A$1090,9,Rank_Changes!$S$2:$S$1090,"Better")-COUNTIFS(Rank_Changes!$E$2:$E$1090,"NLD",Rank_Changes!$A$2:$A$1090,9,Rank_Changes!$S$2:$S$1090,"Worse") -> 0
A25: CHE | B25: =COUNTIFS(Rank_Changes!$E$2:$E$1090,"CHE",Rank_Changes!$A$2:$A$1090,4,Rank_Changes!$S$2:$S$1090,"Better")-COUNTIFS(Rank_Changes!$E$2:$E$1090,"CHE",Rank_Changes!$A$2:$A$1090,4,Rank_Changes!$S$2:$S$1090,"Worse") -> 3 | C25: =COUNTIFS(Rank_Changes!$E$2:$E$1090,"CHE",Rank_Changes!$A$2:$A$1090,10,Rank_Changes!$S$2:$S$1090,"Better")-COUNTIFS(Rank_Changes!$E$2:$E$1090,"CHE",Rank_Changes!$A$2:$A$1090,10,Rank_Changes!$S$2:$S$1090,"Worse") -> -1 | D25: =COUNTIFS(Rank_Changes!$E$2:$E$1090,"CHE",Rank_Changes!$A$2:$A$1090,11,Rank_Changes!$S$2:$S$1090,"Better")-COUNTIFS(Rank_Changes!$E$2:$E$1090,"CHE",Rank_Changes!$A$2:$A$1090,11,Rank_Changes!$S$2:$S$1090,"Worse") -> 1 | E25: =COUNTIFS(Rank_Changes!$E$2:$E$1090,"CHE",Rank_Changes!$A$2:$A$1090,1,Rank_Changes!$S$2:$S$1090,"Better")-COUNTIFS(Rank_Changes!$E$2:$E$1090,"CHE",Rank_Changes!$A$2:$A$1090,1,Rank_Changes!$S$2:$S$1090,"Worse") -> 1 | F25: =COUNTIFS(Rank_Changes!$E$2:$E$1090,"CHE",Rank_Changes!$A$2:$A$1090,9,Rank_Changes!$S$2:$S$1090,"Better")-COUNTIFS(Rank_Changes!$E$2:$E$1090,"CHE",Rank_Changes!$A$2:$A$1090,9,Rank_Changes!$S$2:$S$1090,"Worse") -> 0
A26: Denmark | B26: =COUNTIFS(Rank_Changes!$E$2:$E$1090,"DNK",Rank_Changes!$A$2:$A$1090,4,Rank_Changes!$S$2:$S$1090,"Better")-COUNTIFS(Rank_Changes!$E$2:$E$1090,"DNK",Rank_Changes!$A$2:$A$1090,4,Rank_Changes!$S$2:$S$1090,"Worse") -> 4 | C26: =COUNTIFS(Rank_Changes!$E$2:$E$1090,"DNK",Rank_Changes!$A$2:$A$1090,10,Rank_Changes!$S$2:$S$1090,"Better")-COUNTIFS(Rank_Changes!$E$2:$E$1090,"DNK",Rank_Changes!$A$2:$A$1090,10,Rank_Changes!$S$2:$S$1090,"Worse") -> 1 | D26: =COUNTIFS(Rank_Changes!$E$2:$E$1090,"DNK",Rank_Changes!$A$2:$A$1090,11,Rank_Changes!$S$2:$S$1090,"Better")-COUNTIFS(Rank_Changes!$E$2:$E$1090,"DNK",Rank_Changes!$A$2:$A$1090,11,Rank_Changes!$S$2:$S$1090,"Worse") -> -2 | E26: =COUNTIFS(Rank_Changes!$E$2:$E$1090,"DNK",Rank_Changes!$A$2:$A$1090,1,Rank_Changes!$S$2:$S$1090,"Better")-COUNTIFS(Rank_Changes!$E$2:$E$1090,"DNK",Rank_Changes!$A$2:$A$1090,1,Rank_Changes!$S$2:$S$1090,"Worse") -> 0 | F26: =COUNTIFS(Rank_Changes!$E$2:$E$1090,"DNK",Rank_Changes!$A$2:$A$1090,9,Rank_Changes!$S$2:$S$1090,"Better")-COUNTIFS(Rank_Changes!$E$2:$E$1090,"DNK",Rank_Changes!$A$2:$A$1090,9,Rank_Changes!$S$2:$S$1090,"Worse") -> -1
A27: Canada | B27: =COUNTIFS(Rank_Changes!$E$2:$E$1090,"CAN",Rank_Changes!$A$2:$A$1090,4,Rank_Changes!$S$2:$S$1090,"Better")-COUNTIFS(Rank_Changes!$E$2:$E$1090,"CAN",Rank_Changes!$A$2:$A$1090,4,Rank_Changes!$S$2:$S$1090,"Worse") -> -4 | C27: =COUNTIFS(Rank_Changes!$E$2:$E$1090,"CAN",Rank_Changes!$A$2:$A$1090,10,Rank_Changes!$S$2:$S$1090,"Better")-COUNTIFS(Rank_Changes!$E$2:$E$1090,"CAN",Rank_Changes!$A$2:$A$1090,10,Rank_Changes!$S$2:$S$1090,"Worse") -> 0 | D27: =COUNTIFS(Rank_Changes!$E$2:$E$1090,"CAN",Rank_Changes!$A$2:$A$1090,11,Rank_Changes!$S$2:$S$1090,"Better")-COUNTIFS(Rank_Changes!$E$2:$E$1090,"CAN",Rank_Changes!$A$2:$A$1090,11,Rank_Changes!$S$2:$S$1090,"Worse") -> -1 | E27: =COUNTIFS(Rank_Changes!$E$2:$E$1090,"CAN",Rank_Changes!$A$2:$A$1090,1,Rank_Changes!$S$2:$S$1090,"Better")-COUNTIFS(Rank_Changes!$E$2:$E$1090,"CAN",Rank_Changes!$A$2:$A$1090,1,Rank_Changes!$S$2:$S$1090,"Worse") -> 1 | F27: =COUNTIFS(Rank_Changes!$E$2:$E$1090,"CAN",Rank_Changes!$A$2:$A$1090,9,Rank_Changes!$S$2:$S$1090,"Better")-COUNTIFS(Rank_Changes!$E$2:$E$1090,"CAN",Rank_Changes!$A$2:$A$1090,9,Rank_Changes!$S$2:$S$1090,"Worse") -> 1
A28: Japan | B28: =COUNTIFS(Rank_Changes!$E$2:$E$1090,"JPN",Rank_Changes!$A$2:$A$1090,4,Rank_Changes!$S$2:$S$1090,"Better")-COUNTIFS(Rank_Changes!$E$2:$E$1090,"JPN",Rank_Changes!$A$2:$A$1090,4,Rank_Changes!$S$2:$S$1090,"Worse") -> -1 | C28: =COUNTIFS(Rank_Changes!$E$2:$E$1090,"JPN",Rank_Changes!$A$2:$A$1090,10,Rank_Changes!$S$2:$S$1090,"Better")-COUNTIFS(Rank_Changes!$E$2:$E$1090,"JPN",Rank_Changes!$A$2:$A$1090,10,Rank_Changes!$S$2:$S$1090,"Worse") -> 0 | D28: =COUNTIFS(Rank_Changes!$E$2:$E$1090,"JPN",Rank_Changes!$A$2:$A$1090,11,Rank_Changes!$S$2:$S$1090,"Better")-COUNTIFS(Rank_Changes!$E$2:$E$1090,"JPN",Rank_Changes!$A$2:$A$1090,11,Rank_Changes!$S$2:$S$1090,"Worse") -> 2 | E28: =COUNTIFS(Rank_Changes!$E$2:$E$1090,"JPN",Rank_Changes!$A$2:$A$1090,1,Rank_Changes!$S$2:$S$1090,"Better")-COUNTIFS(Rank_Changes!$E$2:$E$1090,"JPN",Rank_Changes!$A$2:$A$1090,1,Rank_Changes!$S$2:$S$1090,"Worse") -> 0 | F28: =COUNTIFS(Rank_Changes!$E$2:$E$1090,"JPN",Rank_Changes!$A$2:$A$1090,9,Rank_Changes!$S$2:$S$1090,"Better")-COUNTIFS(Rank_Changes!$E$2:$E$1090,"JPN",Rank_Changes!$A$2:$A$1090,9,Rank_Changes!$S$2:$S$1090,"Worse") -> 0
A29: Australia | B29: =COUNTIFS(Rank_Changes!$E$2:$E$1090,"AUS",Rank_Changes!$A$2:$A$1090,4,Rank_Changes!$S$2:$S$1090,"Better")-COUNTIFS(Rank_Changes!$E$2:$E$1090,"AUS",Rank_Changes!$A$2:$A$1090,4,Rank_Changes!$S$2:$S$1090,"Worse") -> -4 | C29: =COUNTIFS(Rank_Changes!$E$2:$E$1090,"AUS",Rank_Changes!$A$2:$A$1090,10,Rank_Changes!$S$2:$S$1090,"Better")-COUNTIFS(Rank_Changes!$E$2:$E$1090,"AUS",Rank_Changes!$A$2:$A$1090,10,Rank_Changes!$S$2:$S$1090,"Worse") -> 3 | D29: =COUNTIFS(Rank_Changes!$E$2:$E$1090,"AUS",Rank_Changes!$A$2:$A$1090,11,Rank_Changes!$S$2:$S$1090,"Better")-COUNTIFS(Rank_Changes!$E$2:$E$1090,"AUS",Rank_Changes!$A$2:$A$1090,11,Rank_Changes!$S$2:$S$1090,"Worse") -> -3 | E29: =COUNTIFS(Rank_Changes!$E$2:$E$1090,"AUS",Rank_Changes!$A$2:$A$1090,1,Rank_Changes!$S$2:$S$1090,"Better")-COUNTIFS(Rank_Changes!$E$2:$E$1090,"AUS",Rank_Changes!$A$2:$A$1090,1,Rank_Changes!$S$2:$S$1090,"Worse") -> -1 | F29: =COUNTIFS(Rank_Changes!$E$2:$E$1090,"AUS",Rank_Changes!$A$2:$A$1090,9,Rank_Changes!$S$2:$S$1090,"Better")-COUNTIFS(Rank_Changes!$E$2:$E$1090,"AUS",Rank_Changes!$A$2:$A$1090,9,Rank_Changes!$S$2:$S$1090,"Worse") -> 0
A30: Domains with directional indicators only (Spending: poverty and coverage; Pharmaceuticals: antibiotic use). Workforce and Utilization indicators are descriptive — see Rank_Movement_Matrix.

Sheet Directions
A1: Indicator ID | B1: Figure | C1: Indicator | D1: Desirable direction (+1 higher better, −1 lower better, 0 none) | E1: Rationale
A2: F1_01 | B2: 1 | C2: Overall population (in millions) | D2: 0 | E2: Descriptive / context: no normative better-or-worse direction
A3: F1_02 | B3: 1 | C3: Population ≥65 y, % | D3: 0 | E3: Descriptive / context: no normative better-or-worse direction
A4: F1_03 | B4: 1 | C4: GDP per capita, US $ (in thousands) | D4: 0 | E4: Descriptive / context: no normative better-or-worse direction
A5: F1_04 | B5: 1 | C5: Land area (× 1000 sq km) | D5: 0 | E5: Descriptive / context: no normative better-or-worse direction
A6: F1_05 | B6: 1 | C6: Poverty rate, % below poverty line of 60% | D6: -1 | E6: Less poverty is better
A7: F1_06 | B7: 1 | C7: Total spending on health, % of total national GDP | D7: 0 | E7: Descriptive / context: no normative better-or-worse direction
A8: F1_07 | B8: 1 | C8: Public spending on health, % of total national GDP | D8: 0 | E8: Descriptive / context: no normative better-or-worse direction
A9: F1_08 | B9: 1 | C9: Mean spending on health per capita, US $ | D9: 0 | E9: Descriptive / context: no normative better-or-worse direction
A10: F1_09 | B10: 1 | C10: Inpatient care | D10: 0 | E10: Descriptive / context: no normative better-or-worse direction
A11: F1_10 | B11: 1 | C11: Outpatient care | D11: 0 | E11: Descriptive / context: no normative better-or-worse direction
A12: F1_11 | B12: 1 | C12: Long-term care | D12: 0 | E12: Descriptive / context: no normative better-or-worse direction
A13: F1_12 | B13: 1 | C13: Medical goods | D13: 0 | E13: Descriptive / context: no normative better-or-worse direction
... A100: F11_10 | B100: 11 | C100: Rural physicians per 1000 population | D100: 0 | E100: Descriptive / context: no normative better-or-worse direction

Sheet Rank_Changes
A1: Figure | B1: Domain | C1: Indicator ID | D1: Indicator | E1: Country | F1: Country label | G1: 2018 value (paper) | H1: 2026 value | I1: 2026 obs. year | J1: Rank in 2018 figure | K1: Rank in 2026 figure | L1: Include (1/0) | M1: n compared | N1: Rank 2018 (common set) | O1: Rank 2026 (common set) | P1: Rank change (+ = up) | Q1: Desirable direction | R1: Performance change (+ = better) | S1: Relative performance | T1: Comparability note | U1: Key
A2: 1 | B2: Spending | C2: F1_01 | D2: Overall population (in millions) | E2: USA | F2: US | G2: 323 | H2: 341.785 | I2: 2025 | J2: 1 | K2: 1 | L2: 1 | M2: =IF(L2=1,COUNTIFS($C$2:$C$1090,C2,$L$2:$L$1090,1),"") -> 11 | N2: =IF(L2=1,1+COUNTIFS($C$2:$C$1090,C2,$L$2:$L$1090,1,$G$2:$G$1090,">"&G2),"") -> 1 | O2: =IF(L2=1,1+COUNTIFS($C$2:$C$1090,C2,$L$2:$L$1090,1,$H$2:$H$1090,">"&H2),"") -> 1 | P2: =IF(L2=1,N2-O2,"") -> 0 | Q2: =INDEX(Directions!$D$2:$D$100,MATCH(C2,Directions!$A$2:$A$100,0)) -> 0 | R2: =IF(L2=1,P2*Q2,"") -> 0 | S2: =IF(L2<>1,"Excluded",IF(Q2=0,"No direction",IF(R2>0,"Better",IF(R2<0,"Worse","No change")))) -> No direction | U2: =C2&"|"&E2 -> F1_01|USA
A3: 1 | B3: Spending | C3: F1_01 | D3: Overall population (in millions) | E3: GBR | F3: UK | G3: 66 | H3: 69.487 | I3: 2025 | J3: 4 | K3: 4 | L3: 1 | M3: =IF(L3=1,COUNTIFS($C$2:$C$1090,C3,$L$2:$L$1090,1),"") -> 11 | N3: =IF(L3=1,1+COUNTIFS($C$2:$C$1090,C3,$L$2:$L$1090,1,$G$2:$G$1090,">"&G3),"") -> 4 | O3: =IF(L3=1,1+COUNTIFS($C$2:$C$1090,C3,$L$2:$L$1090,1,$H$2:$H$1090,">"&H3),"") -> 4 | P3: =IF(L3=1,N3-O3,"") -> 0 | Q3: =INDEX(Directions!$D$2:$D$100,MATCH(C3,Directions!$A$2:$A$100,0)) -> 0 | R3: =IF(L3=1,P3*Q3,"") -> 0 | S3: =IF(L3<>1,"Excluded",IF(Q3=0,"No direction",IF(R3>0,"Better",IF(R3<0,"Worse","No change")))) -> No direction | U3: =C3&"|"&E3 -> F1_01|GBR
A4: 1 | B4: Spending | C4: F1_01 | D4: Overall population (in millions) | E4: DEU | F4: Germany | G4: 83 | H4: 83.491 | I4: 2025 | J4: 3 | K4: 3 | L4: 1 | M4: =IF(L4=1,COUNTIFS($C$2:$C$1090,C4,$L$2:$L$1090,1),"") -> 11 | N4: =IF(L4=1,1+COUNTIFS($C$2:$C$1090,C4,$L$2:$L$1090,1,$G$2:$G$1090,">"&G4),"") -> 3 | O4: =IF(L4=1,1+COUNTIFS($C$2:$C$1090,C4,$L$2:$L$1090,1,$H$2:$H$1090,">"&H4),"") -> 3 | P4: =IF(L4=1,N4-O4,"") -> 0 | Q4: =INDEX(Directions!$D$2:$D$100,MATCH(C4,Directions!$A$2:$A$100,0)) -> 0 | R4: =IF(L4=1,P4*Q4,"") -> 0 | S4: =IF(L4<>1,"Excluded",IF(Q4=0,"No direction",IF(R4>0,"Better",IF(R4<0,"Worse","No change")))) -> No direction | U4: =C4&"|"&E4 -> F1_01|DEU
A5: 1 | B5: Spending | C5: F1_01 | D5: Overall population (in millions) | E5: SWE | F5: Sweden | G5: 10 | H5: 10.597 | I5: 2025 | J5: 9 | K5: 9 | L5: 1 | M5: =IF(L5=1,COUNTIFS($C$2:$C$1090,C5,$L$2:$L$1090,1),"") -> 11 | N5: =IF(L5=1,1+COUNTIFS($C$2:$C$1090,C5,$L$2:$L$1090,1,$G$2:$G$1090,">"&G5),"") -> 9 | O5: =IF(L5=1,1+COUNTIFS($C$2:$C$1090,C5,$L$2:$L$1090,1,$H$2:$H$1090,">"&H5),"") -> 9 | P5: =IF(L5=1,N5-O5,"") -> 0 | Q5: =INDEX(Directions!$D$2:$D$100,MATCH(C5,Directions!$A$2:$A$100,0)) -> 0 | R5: =IF(L5=1,P5*Q5,"") -> 0 | S5: =IF(L5<>1,"Excluded",IF(Q5=0,"No direction",IF(R5>0,"Better",IF(R5<0,"Worse","No change")))) -> No direction | U5: =C5&"|"&E5 -> F1_01|SWE
A6: 1 | B6: Spending | C6: F1_01 | D6: Overall population (in millions) | E6: FRA | F6: France | G6: 64 | H6: 68.72 | I6: 2025 | J6: 5 | K6: 5 | L6: 1 | M6: =IF(L6=1,COUNTIFS($C$2:$C$1090,C6,$L$2:$L$1090,1),"") -> 11 | N6: =IF(L6=1,1+COUNTIFS($C$2:$C$1090,C6,$L$2:$L$1090,1,$G$2:$G$1090,">"&G6),"") -> 5 | O6: =IF(L6=1,1+COUNTIFS($C$2:$C$1090,C6,$L$2:$L$1090,1,$H$2:$H$1090,">"&H6),"") -> 5 | P6: =IF(L6=1,N6-O6,"") -> 0 | Q6: =INDEX(Directions!$D$2:$D$100,MATCH(C6,Directions!$A$2:$A$100,0)) -> 0 | R6: =IF(L6=1,P6*Q6,"") -> 0 | S6: =IF(L6<>1,"Excluded",IF(Q6=0,"No direction",IF(R6>0,"Better",IF(R6<0,"Worse","No change")))) -> No direction | U6: =C6&"|"&E6 -> F1_01|FRA
A7: 1 | B7: Spending | C7: F1_01 | D7: Overall population (in millions) | E7: NLD | F7: NLD | G7: 17 | H7: 18.088 | I7: 2025 | J7: 8 | K7: 8 | L7: 1 | M7: =IF(L7=1,COUNTIFS($C$2:$C$1090,C7,$L$2:$L$1090,1),"") -> 11 | N7: =IF(L7=1,1+COUNTIFS($C$2:$C$1090,C7,$L$2:$L$1090,1,$G$2:$G$1090,">"&G7),"") -> 8 | O7: =IF(L7=1,1+COUNTIFS($C$2:$C$1090,C7,$L$2:$L$1090,1,$H$2:$H$1090,">"&H7),"") -> 8 | P7: =IF(L7=1,N7-O7,"") -> 0 | Q7: =INDEX(Directions!$D$2:$D$100,MATCH(C7,Directions!$A$2:$A$100,0)) -> 0 | R7: =IF(L7=1,P7*Q7,"") -> 0 | S7: =IF(L7<>1,"Excluded",IF(Q7=0,"No direction",IF(R7>0,"Better",IF(R7<0,"Worse","No change")))) -> No direction | U7: =C7&"|"&E7 -> F1_01|NLD
A8: 1 | B8: Spending | C8: F1_01 | D8: Overall population (in millions) | E8: CHE | F8: CHE | G8: 8 | H8: 9.092 | I8: 2025 | J8: 10 | K8: 10 | L8: 1 | M8: =IF(L8=1,COUNTIFS($C$2:$C$1090,C8,$L$2:$L$1090,1),"") -> 11 | N8: =IF(L8=1,1+COUNTIFS($C$2:$C$1090,C8,$L$2:$L$1090,1,$G$2:$G$1090,">"&G8),"") -> 10 | O8: =IF(L8=1,1+COUNTIFS($C$2:$C$1090,C8,$L$2:$L$1090,1,$H$2:$H$1090,">"&H8),"") -> 10 | P8: =IF(L8=1,N8-O8,"") -> 0 | Q8: =INDEX(Directions!$D$2:$D$100,MATCH(C8,Directions!$A$2:$A$100,0)) -> 0 | R8: =IF(L8=1,P8*Q8,"") -> 0 | S8: =IF(L8<>1,"Excluded",IF(Q8=0,"No direction",IF(R8>0,"Better",IF(R8<0,"Worse","No change")))) -> No direction | U8: =C8&"|"&E8 -> F1_01|CHE
A9: 1 | B9: Spending | C9: F1_01 | D9: Overall population (in millions) | E9: DNK | F9: Denmark | G9: 6 | H9: 6.009 | I9: 2025 | J9: 11 | K9: 11 | L9: 1 | M9: =IF(L9=1,COUNTIFS($C$2:$C$1090,C9,$L$2:$L$1090,1),"") -> 11 | N9: =IF(L9=1,1+COUNTIFS($C$2:$C$1090,C9,$L$2:$L$1090,1,$G$2:$G$1090,">"&G9),"") -> 11 | O9: =IF(L9=1,1+COUNTIFS($C$2:$C$1090,C9,$L$2:$L$1090,1,$H$2:$H$1090,">"&H9),"") -> 11 | P9: =IF(L9=1,N9-O9,"") -> 0 | Q9: =INDEX(Directions!$D$2:$D$100,MATCH(C9,Directions!$A$2:$A$100,0)) -> 0 | R9: =IF(L9=1,P9*Q9,"") -> 0 | S9: =IF(L9<>1,"Excluded",IF(Q9=0,"No direction",IF(R9>0,"Better",IF(R9<0,"Worse","No change")))) -> No direction | U9: =C9&"|"&E9 -> F1_01|DNK
A10: 1 | B10: Spending | C10: F1_01 | D10: Overall population (in millions) | E10: CAN | F10: Canada | G10: 36 | H10: 41.652 | I10: 2025 | J10: 6 | K10: 6 | L10: 1 | M10: =IF(L10=1,COUNTIFS($C$2:$C$1090,C10,$L$2:$L$1090,1),"") -> 11 | N10: =IF(L10=1,1+COUNTIFS($C$2:$C$1090,C10,$L$2:$L$1090,1,$G$2:$G$1090,">"&G10),"") -> 6 | O10: =IF(L10=1,1+COUNTIFS($C$2:$C$1090,C10,$L$2:$L$1090,1,$H$2:$H$1090,">"&H10),"") -> 6 | P10: =IF(L10=1,N10-O10,"") -> 0 | Q10: =INDEX(Directions!$D$2:$D$100,MATCH(C10,Directions!$A$2:$A$100,0)) -> 0 | R10: =IF(L10=1,P10*Q10,"") -> 0 | S10: =IF(L10<>1,"Excluded",IF(Q10=0,"No direction",IF(R10>0,"Better",IF(R10<0,"Worse","No change")))) -> No direction | U10: =C10&"|"&E10 -> F1_01|CAN
A11: 1 | B11: Spending | C11: F1_01 | D11: Overall population (in millions) | E11: JPN | F11: Japan | G11: 127 | H11: 123.367 | I11: 2025 | J11: 2 | K11: 2 | L11: 1 | M11: =IF(L11=1,COUNTIFS($C$2:$C$1090,C11,$L$2:$L$1090,1),"") -> 11 | N11: =IF(L11=1,1+COUNTIFS($C$2:$C$1090,C11,$L$2:$L$1090,1,$G$2:$G$1090,">"&G11),"") -> 2 | O11: =IF(L11=1,1+COUNTIFS($C$2:$C$1090,C11,$L$2:$L$1090,1,$H$2:$H$1090,">"&H11),"") -> 2 | P11: =IF(L11=1,N11-O11,"") -> 0 | Q11: =INDEX(Directions!$D$2:$D$100,MATCH(C11,Directions!$A$2:$A$100,0)) -> 0 | R11: =IF(L11=1,P11*Q11,"") -> 0 | S11: =IF(L11<>1,"Excluded",IF(Q11=0,"No direction",IF(R11>0,"Better",IF(R11<0,"Worse","No change")))) -> No direction | U11: =C11&"|"&E11 -> F1_01|JPN
A12: 1 | B12: Spending | C12: F1_01 | D12: Overall population (in millions) | E12: AUS | F12: Australia | G12: 24 | H12: 27.614 | I12: 2025 | J12: 7 | K12: 7 | L12: 1 | M12: =IF(L12=1,COUNTIFS($C$2:$C$1090,C12,$L$2:$L$1090,1),"") -> 11 | N12: =IF(L12=1,1+COUNTIFS($C$2:$C$1090,C12,$L$2:$L$1090,1,$G$2:$G$1090,">"&G12),"") -> 7 | O12: =IF(L12=1,1+COUNTIFS($C$2:$C$1090,C12,$L$2:$L$1090,1,$H$2:$H$1090,">"&H12),"") -> 7 | P12: =IF(L12=1,N12-O12,"") -> 0 | Q12: =INDEX(Directions!$D$2:$D$100,MATCH(C12,Directions!$A$2:$A$100,0)) -> 0 | R12: =IF(L12=1,P12*Q12,"") -> 0 | S12: =IF(L12<>1,"Excluded",IF(Q12=0,"No direction",IF(R12>0,"Better",IF(R12<0,"Worse","No change")))) -> No direction | U12: =C12&"|"&E12 -> F1_01|AUS
A13: 1 | B13: Spending | C13: F1_02 | D13: Population ≥65 y, % | E13: USA | F13: US | G13: 14.5 | H13: 18.9 | I13: 2025 | J13: 11 | K13: 10 | L13: 1 | M13: =IF(L13=1,COUNTIFS($C$2:$C$1090,C13,$L$2:$L$1090,1),"") -> 11 | N13: =IF(L13=1,1+COUNTIFS($C$2:$C$1090,C13,$L$2:$L$1090,1,$G$2:$G$1090,">"&G13),"") -> 11 | O13: =IF(L13=1,1+COUNTIFS($C$2:$C$1090,C13,$L$2:$L$1090,1,$H$2:$H$1090,">"&H13),"") -> 10 | P13: =IF(L13=1,N13-O13,"") -> 1 | Q13: =INDEX(Directions!$D$2:$D$100,MATCH(C13,Directions!$A$2:$A$100,0)) -> 0 | R13: =IF(L13=1,P13*Q13,"") -> 0 | S13: =IF(L13<>1,"Excluded",IF(Q13=0,"No direction",IF(R13>0,"Better",IF(R13<0,"Worse","No change")))) -> No direction | U13: =C13&"|"&E13 -> F1_02|USA
... A34: 1 | B34: Spending | C34: F1_03 | D34: GDP per capita, US $ (in thousands) | E34: AUS | F34: Australia | G34: 45.1 | H34: 75.21 | I34: 2025 | J34: 6 | K34: 6 | L34: 1 | M34: =IF(L34=1,COUNTIFS($C$2:$C$1090,C34,$L$2:$L$1090,1),"") -> 11 | N34: =IF(L34=1,1+COUNTIFS($C$2:$C$1090,C34,$L$2:$L$1090,1,$G$2:$G$1090,">"&G34),"") -> 6 | O34: =IF(L34=1,1+COUNTIFS($C$2:$C$1090,C34,$L$2:$L$1090,1,$H$2:$H$1090,">"&H34),"") -> 6 | P34: =IF(L34=1,N34-O34,"") -> 0 | Q34: =INDEX(Directions!$D$2:$D$100,MATCH(C34,Directions!$A$2:$A$100,0)) -> 0 | R34: =IF(L34=1,P34*Q34,"") -> 0 | S34: =IF(L34<>1,"Excluded",IF(Q34=0,"No direction",IF(R34>0,"Better",IF(R34<0,"Worse","No change")))) -> No direction | U34: =C34&"|"&E34 -> F1_03|AUS
A35: 1 | B35: Spending | C35: F1_04 | D35: Land area (× 1000 sq km) | E35: USA | F35: US | G35: 9834 | H35: 9147.4 | I35: 2023 | J35: 2 | K35: 1 | L35: 1 | M35: =IF(L35=1,COUNTIFS($C$2:$C$1090,C35,$L$2:$L$1090,1),"") -> 11 | N35: =IF(L35=1,1+COUNTIFS($C$2:$C$1090,C35,$L$2:$L$1090,1,$G$2:$G$1090,">"&G35),"") -> 2 | O35: =IF(L35=1,1+COUNTIFS($C$2:$C$1090,C35,$L$2:$L$1090,1,$H$2:$H$1090,">"&H35),"") -> 1 | P35: =IF(L35=1,N35-O35,"") -> 1 | Q35: =INDEX(Directions!$D$2:$D$100,MATCH(C35,Directions!$A$2:$A$100,0)) -> 0 | R35: =IF(L35=1,P35*Q35,"") -> 0 | S35: =IF(L35<>1,"Excluded",IF(Q35=0,"No direction",IF(R35>0,"Better",IF(R35<0,"Worse","No change")))) -> No direction | T35: Land area now vs surface area in 2018 (Canada/US order is an artifact) | U35: =C35&"|"&E35 -> F1_04|USA
A36: 1 | B36: Spending | C36: F1_04 | D36: Land area (× 1000 sq km) | E36: GBR | F36: UK | G36: 244 | H36: 241.9 | I36: 2023 | J36: 8 | K36: 8 | L36: 1 | M36: =IF(L36=1,COUNTIFS($C$2:$C$1090,C36,$L$2:$L$1090,1),"") -> 11 | N36: =IF(L36=1,1+COUNTIFS($C$2:$C$1090,C36,$L$2:$L$1090,1,$G$2:$G$1090,">"&G36),"") -> 8 | O36: =IF(L36=1,1+COUNTIFS($C$2:$C$1090,C36,$L$2:$L$1090,1,$H$2:$H$1090,">"&H36),"") -> 8 | P36: =IF(L36=1,N36-O36,"") -> 0 | Q36: =INDEX(Directions!$D$2:$D$100,MATCH(C36,Directions!$A$2:$A$100,0)) -> 0 | R36: =IF(L36=1,P36*Q36,"") -> 0 | S36: =IF(L36<>1,"Excluded",IF(Q36=0,"No direction",IF(R36>0,"Better",IF(R36<0,"Worse","No change")))) -> No direction | T36: Land area now vs surface area in 2018 (Canada/US order is an artifact) | U36: =C36&"|"&E36 -> F1_04|GBR
A37: 1 | B37: Spending | C37: F1_04 | D37: Land area (× 1000 sq km) | E37: DEU | F37: Germany | G37: 357 | H37: 349.4 | I37: 2023 | J37: 7 | K37: 7 | L37: 1 | M37: =IF(L37=1,COUNTIFS($C$2:$C$1090,C37,$L$2:$L$1090,1),"") -> 11 | N37: =IF(L37=1,1+COUNTIFS($C$2:$C$1090,C37,$L$2:$L$1090,1,$G$2:$G$1090,">"&G37),"") -> 7 | O37: =IF(L37=1,1+COUNTIFS($C$2:$C$1090,C37,$L$2:$L$1090,1,$H$2:$H$1090,">"&H37),"") -> 7 | P37: =IF(L37=1,N37-O37,"") -> 0 | Q37: =INDEX(Directions!$D$2:$D$100,MATCH(C37,Directions!$A$2:$A$100,0)) -> 0 | R37: =IF(L37=1,P37*Q37,"") -> 0 | S37: =IF(L37<>1,"Excluded",IF(Q37=0,"No direction",IF(R37>0,"Better",IF(R37<0,"Worse","No change")))) -> No direction | T37: Land area now vs surface area in 2018 (Canada/US order is an artifact) | U37: =C37&"|"&E37 -> F1_04|DEU
A38: 1 | B38: Spending | C38: F1_04 | D38: Land area (× 1000 sq km) | E38: SWE | F38: Sweden | G38: 450 | H38: 407.3 | I38: 2023 | J38: 5 | K38: 5 | L38: 1 | M38: =IF(L38=1,COUNTIFS($C$2:$C$1090,C38,$L$2:$L$1090,1),"") -> 11 | N38: =IF(L38=1,1+COUNTIFS($C$2:$C$1090,C38,$L$2:$L$1090,1,$G$2:$G$1090,">"&G38),"") -> 5 | O38: =IF(L38=1,1+COUNTIFS($C$2:$C$1090,C38,$L$2:$L$1090,1,$H$2:$H$1090,">"&H38),"") -> 5 | P38: =IF(L38=1,N38-O38,"") -> 0 | Q38: =INDEX(Directions!$D$2:$D$100,MATCH(C38,Directions!$A$2:$A$100,0)) -> 0 | R38: =IF(L38=1,P38*Q38,"") -> 0 | S38: =IF(L38<>1,"Excluded",IF(Q38=0,"No direction",IF(R38>0,"Better",IF(R38<0,"Worse","No change")))) -> No direction | T38: Land area now vs surface area in 2018 (Canada/US order is an artifact) | U38: =C38&"|"&E38 -> F1_04|SWE
A39: 1 | B39: Spending | C39: F1_04 | D39: Land area (× 1000 sq km) | E39: FRA | F39: France | G39: 549 | H39: 539 | I39: 2023 | J39: 4 | K39: 4 | L39: 1 | M39: =IF(L39=1,COUNTIFS($C$2:$C$1090,C39,$L$2:$L$1090,1),"") -> 11 | N39: =IF(L39=1,1+COUNTIFS($C$2:$C$1090,C39,$L$2:$L$1090,1,$G$2:$G$1090,">"&G39),"") -> 4 | O39: =IF(L39=1,1+COUNTIFS($C$2:$C$1090,C39,$L$2:$L$1090,1,$H$2:$H$1090,">"&H39),"") -> 4 | P39: =IF(L39=1,N39-O39,"") -> 0 | Q39: =INDEX(Directions!$D$2:$D$100,MATCH(C39,Directions!$A$2:$A$100,0)) -> 0 | R39: =IF(L39=1,P39*Q39,"") -> 0 | S39: =IF(L39<>1,"Excluded",IF(Q39=0,"No direction",IF(R39>0,"Better",IF(R39<0,"Worse","No change")))) -> No direction | T39: Land area now vs surface area in 2018 (Canada/US order is an artifact) | U39: =C39&"|"&E39 -> F1_04|FRA
A40: 1 | B40: Spending | C40: F1_04 | D40: Land area (× 1000 sq km) | E40: NLD | F40: NLD | G40: 42 | H40: 33.7 | I40: 2023 | J40: 10 | K40: 11 | L40: 1 | M40: =IF(L40=1,COUNTIFS($C$2:$C$1090,C40,$L$2:$L$1090,1),"") -> 11 | N40: =IF(L40=1,1+COUNTIFS($C$2:$C$1090,C40,$L$2:$L$1090,1,$G$2:$G$1090,">"&G40),"") -> 10 | O40: =IF(L40=1,1+COUNTIFS($C$2:$C$1090,C40,$L$2:$L$1090,1,$H$2:$H$1090,">"&H40),"") -> 11 | P40: =IF(L40=1,N40-O40,"") -> -1 | Q40: =INDEX(Directions!$D$2:$D$100,MATCH(C40,Directions!$A$2:$A$100,0)) -> 0 | R40: =IF(L40=1,P40*Q40,"") -> 0 | S40: =IF(L40<>1,"Excluded",IF(Q40=0,"No direction",IF(R40>0,"Better",IF(R40<0,"Worse","No change")))) -> No direction | T40: Land area now vs surface area in 2018 (Canada/US order is an artifact) | U40: =C40&"|"&E40 -> F1_04|NLD
A41: 1 | B41: Spending | C41: F1_04 | D41: Land area (× 1000 sq km) | E41: CHE | F41: CHE | G41: 42 | H41: 39.5 | I41: 2023 | J41: 11 | K41: 10 | L41: 1 | M41: =IF(L41=1,COUNTIFS($C$2:$C$1090,C41,$L$2:$L$1090,1),"") -> 11 | N41: =IF(L41=1,1+COUNTIFS($C$2:$C$1090,C41,$L$2:$L$1090,1,$G$2:$G$1090,">"&G41),"") -> 10 | O41: =IF(L41=1,1+COUNTIFS($C$2:$C$1090,C41,$L$2:$L$1090,1,$H$2:$H$1090,">"&H41),"") -> 10 | P41: =IF(L41=1,N41-O41,"") -> 0 | Q41: =INDEX(Directions!$D$2:$D$100,MATCH(C41,Directions!$A$2:$A$100,0)) -> 0 | R41: =IF(L41=1,P41*Q41,"") -> 0 | S41: =IF(L41<>1,"Excluded",IF(Q41=0,"No direction",IF(R41>0,"Better",IF(R41<0,"Worse","No change")))) -> No direction | T41: Land area now vs surface area in 2018 (Canada/US order is an artifact) | U41: =C41&"|"&E41 -> F1_04|CHE
A42: 1 | B42: Spending | C42: F1_04 | D42: Land area (× 1000 sq km) | E42: DNK | F42: Denmark | G42: 43 | H42: 40 | I42: 2023 | J42: 9 | K42: 9 | L42: 1 | M42: =IF(L42=1,COUNTIFS($C$2:$C$1090,C42,$L$2:$L$1090,1),"") -> 11 | N42: =IF(L42=1,1+COUNTIFS($C$2:$C$1090,C42,$L$2:$L$1090,1,$G$2:$G$1090,">"&G42),"") -> 9 | O42: =IF(L42=1,1+COUNTIFS($C$2:$C$1090,C42,$L$2:$L$1090,1,$H$2:$H$1090,">"&H42),"") -> 9 | P42: =IF(L42=1,N42-O42,"") -> 0 | Q42: =INDEX(Directions!$D$2:$D$100,MATCH(C42,Directions!$A$2:$A$100,0)) -> 0 | R42: =IF(L42=1,P42*Q42,"") -> 0 | S42: =IF(L42<>1,"Excluded",IF(Q42=0,"No direction",IF(R42>0,"Better",IF(R42<0,"Worse","No change")))) -> No direction | T42: Land area now vs surface area in 2018 (Canada/US order is an artifact) | U42: =C42&"|"&E42 -> F1_04|DNK
A43: 1 | B43: Spending | C43: F1_04 | D43: Land area (× 1000 sq km) | E43: CAN | F43: Canada | G43: 9985 | H43: 8788.7 | I43: 2023 | J43: 1 | K43: 2 | L43: 1 | M43: =IF(L43=1,COUNTIFS($C$2:$C$1090,C43,$L$2:$L$1090,1),"") -> 11 | N43: =IF(L43=1,1+COUNTIFS($C$2:$C$1090,C43,$L$2:$L$1090,1,$G$2:$G$1090,">"&G43),"") -> 1 | O43: =IF(L43=1,1+COUNTIFS($C$2:$C$1090,C43,$L$2:$L$1090,1,$H$2:$H$1090,">"&H43),"") -> 2 | P43: =IF(L43=1,N43-O43,"") -> -1 | Q43: =INDEX(Directions!$D$2:$D$100,MATCH(C43,Directions!$A$2:$A$100,0)) -> 0 | R43: =IF(L43=1,P43*Q43,"") -> 0 | S43: =IF(L43<>1,"Excluded",IF(Q43=0,"No direction",IF(R43>0,"Better",IF(R43<0,"Worse","No change")))) -> No direction | T43: Land area now vs surface area in 2018 (Canada/US order is an artifact) | U43: =C43&"|"&E43 -> F1_04|CAN
A44: 1 | B44: Spending | C44: F1_04 | D44: Land area (× 1000 sq km) | E44: JPN | F44: Japan | G44: 378 | H44: 364.6 | I44: 2023 | J44: 6 | K44: 6 | L44: 1 | M44: =IF(L44=1,COUNTIFS($C$2:$C$1090,C44,$L$2:$L$1090,1),"") -> 11 | N44: =IF(L44=1,1+COUNTIFS($C$2:$C$1090,C44,$L$2:$L$1090,1,$G$2:$G$1090,">"&G44),"") -> 6 | O44: =IF(L44=1,1+COUNTIFS($C$2:$C$1090,C44,$L$2:$L$1090,1,$H$2:$H$1090,">"&H44),"") -> 6 | P44: =IF(L44=1,N44-O44,"") -> 0 | Q44: =INDEX(Directions!$D$2:$D$100,MATCH(C44,Directions!$A$2:$A$100,0)) -> 0 | R44: =IF(L44=1,P44*Q44,"") -> 0 | S44: =IF(L44<>1,"Excluded",IF(Q44=0,"No direction",IF(R44>0,"Better",IF(R44<0,"Worse","No change")))) -> No direction | T44: Land area now vs surface area in 2018 (Canada/US order is an artifact) | U44: =C44&"|"&E44 -> F1_04|JPN
A45: 1 | B45: Spending | C45: F1_04 | D45: Land area (× 1000 sq km) | E45: AUS | F45: Australia | G45: 7741 | H45: 7692 | I45: 2023 | J45: 3 | K45: 3 | L45: 1 | M45: =IF(L45=1,COUNTIFS($C$2:$C$1090,C45,$L$2:$L$1090,1),"") -> 11 | N45: =IF(L45=1,1+COUNTIFS($C$2:$C$1090,C45,$L$2:$L$1090,1,$G$2:$G$1090,">"&G45),"") -> 3 | O45: =IF(L45=1,1+COUNTIFS($C$2:$C$1090,C45,$L$2:$L$1090,1,$H$2:$H$1090,">"&H45),"") -> 3 | P45: =IF(L45=1,N45-O45,"") -> 0 | Q45: =INDEX(Directions!$D$2:$D$100,MATCH(C45,Directions!$A$2:$A$100,0)) -> 0 | R45: =IF(L45=1,P45*Q45,"") -> 0 | S45: =IF(L45<>1,"Excluded",IF(Q45=0,"No direction",IF(R45>0,"Better",IF(R45<0,"Worse","No change")))) -> No direction | T45: Land area now vs surface area in 2018 (Canada/US order is an artifact) | U45: =C45&"|"&E45 -> F1_04|AUS
A46: 1 | B46: Spending | C46: F1_05 | D46: Poverty rate, % below poverty line of 60% | E46: USA | F46: US | G46: 24 | H46: 25.1 | I46: 2023 | J46: 1 | K46: 1 | L46: 1 | M46: =IF(L46=1,COUNTIFS($C$2:$C$1090,C46,$L$2:$L$1090,1),"") -> 11 | N46: =IF(L46=1,1+COUNTIFS($C$2:$C$1090,C46,$L$2:$L$1090,1,$G$2:$G$1090,">"&G46),"") -> 1 | O46: =IF(L46=1,1+COUNTIFS($C$2:$C$1090,C46,$L$2:$L$1090,1,$H$2:$H$1090,">"&H46),"") -> 1 | P46: =IF(L46=1,N46-O46,"") -> 0 | Q46: =INDEX(Directions!$D$2:$D$100,MATCH(C46,Directions!$A$2:$A$100,0)) -> -1 | R46: =IF(L46=1,P46*Q46,"") -> 0 | S46: =IF(L46<>1,"Excluded",IF(Q46=0,"No direction",IF(R46>0,"Better",IF(R46<0,"Worse","No change")))) -> No change | U46: =C46&"|"&E46 -> F1_05|USA
A47: 1 | B47: Spending | C47: F1_05 | D47: Poverty rate, % below poverty line of 60% | E47: GBR | F47: UK | G47: 18 | H47: 18.4 | I47: 2023 | J47: 5 | K47: 5 | L47: 1 | M47: =IF(L47=1,COUNTIFS($C$2:$C$1090,C47,$L$2:$L$1090,1),"") -> 11 | N47: =IF(L47=1,1+COUNTIFS($C$2:$C$1090,C47,$L$2:$L$1090,1,$G$2:$G$1090,">"&G47),"") -> 5 | O47: =IF(L47=1,1+COUNTIFS($C$2:$C$1090,C47,$L$2:$L$1090,1,$H$2:$H$1090,">"&H47),"") -> 5 | P47: =IF(L47=1,N47-O47,"") -> 0 | Q47: =INDEX(Directions!$D$2:$D$100,MATCH(C47,Directions!$A$2:$A$100,0)) -> -1 | R47: =IF(L47=1,P47*Q47,"") -> 0 | S47: =IF(L47<>1,"Excluded",IF(Q47=0,"No direction",IF(R47>0,"Better",IF(R47<0,"Worse","No change")))) -> No change | U47: =C47&"|"&E47 -> F1_05|GBR
A48: 1 | B48: Spending | C48: F1_05 | D48: Poverty rate, % below poverty line of 60% | E48: DEU | F48: Germany | G48: 16 | H48: 17.5 | I48: 2023 | J48: 8 | K48: 6 | L48: 1 | M48: =IF(L48=1,COUNTIFS($C$2:$C$1090,C48,$L$2:$L$1090,1),"") -> 11 | N48: =IF(L48=1,1+COUNTIFS($C$2:$C$1090,C48,$L$2:$L$1090,1,$G$2:$G$1090,">"&G48),"") -> 8 | O48: =IF(L48=1,1+COUNTIFS($C$2:$C$1090,C48,$L$2:$L$1090,1,$H$2:$H$1090,">"&H48),"") -> 6 | P48: =IF(L48=1,N48-O48,"") -> 2 | Q48: =INDEX(Directions!$D$2:$D$100,MATCH(C48,Directions!$A$2:$A$100,0)) -> -1 | R48: =IF(L48=1,P48*Q48,"") -> -2 | S48: =IF(L48<>1,"Excluded",IF(Q48=0,"No direction",IF(R48>0,"Better",IF(R48<0,"Worse","No change")))) -> Worse | U48: =C48&"|"&E48 -> F1_05|DEU
A49: 1 | B49: Spending | C49: F1_05 | D49: Poverty rate, % below poverty line of 60% | E49: SWE | F49: Sweden | G49: 17 | H49: 15.5 | I49: 2024 | J49: 6 | K49: 8 | L49: 1 | M49: =IF(L49=1,COUNTIFS($C$2:$C$1090,C49,$L$2:$L$1090,1),"") -> 11 | N49: =IF(L49=1,1+COUNTIFS($C$2:$C$1090,C49,$L$2:$L$1090,1,$G$2:$G$1090,">"&G49),"") -> 6 | O49: =IF(L49=1,1+COUNTIFS($C$2:$C$1090,C49,$L$2:$L$1090,1,$H$2:$H$1090,">"&H49),"") -> 8 | P49: =IF(L49=1,N49-O49,"") -> -2 | Q49: =INDEX(Directions!$D$2:$D$100,MATCH(C49,Directions!$A$2:$A$100,0)) -> -1 | R49: =IF(L49=1,P49*Q49,"") -> 2 | S49: =IF(L49<>1,"Excluded",IF(Q49=0,"No direction",IF(R49>0,"Better",IF(R49<0,"Worse","No change")))) -> Better | U49: =C49&"|"&E49 -> F1_05|SWE
A50: 1 | B50: Spending | C50: F1_05 | D50: Poverty rate, % below poverty line of 60% | E50: FRA | F50: France | G50: 15 | H50: 15.4 | I50: 2023 | J50: 9 | K50: 9 | L50: 1 | M50: =IF(L50=1,COUNTIFS($C$2:$C$1090,C50,$L$2:$L$1090,1),"") -> 11 | N50: =IF(L50=1,1+COUNTIFS($C$2:$C$1090,C50,$L$2:$L$1090,1,$G$2:$G$1090,">"&G50),"") -> 9 | O50: =IF(L50=1,1+COUNTIFS($C$2:$C$1090,C50,$L$2:$L$1090,1,$H$2:$H$1090,">"&H50),"") -> 9 | P50: =IF(L50=1,N50-O50,"") -> 0 | Q50: =INDEX(Directions!$D$2:$D$100,MATCH(C50,Directions!$A$2:$A$100,0)) -> -1 | R50: =IF(L50=1,P50*Q50,"") -> 0 | S50: =IF(L50<>1,"Excluded",IF(Q50=0,"No direction",IF(R50>0,"Better",IF(R50<0,"Worse","No change")))) -> No change | U50: =C50&"|"&E50 -> F1_05|FRA
A51: 1 | B51: Spending | C51: F1_05 | D51: Poverty rate, % below poverty line of 60% | E51: NLD | F51: NLD | G51: 15 | H51: 15 | I51: 2024 | J51: 10 | K51: 10 | L51: 1 | M51: =IF(L51=1,COUNTIFS($C$2:$C$1090,C51,$L$2:$L$1090,1),"") -> 11 | N51: =IF(L51=1,1+COUNTIFS($C$2:$C$1090,C51,$L$2:$L$1090,1,$G$2:$G$1090,">"&G51),"") -> 9 | O51: =IF(L51=1,1+COUNTIFS($C$2:$C$1090,C51,$L$2:$L$1090,1,$H$2:$H$1090,">"&H51),"") -> 10 | P51: =IF(L51=1,N51-O51,"") -> -1 | Q51: =INDEX(Directions!$D$2:$D$100,MATCH(C51,Directions!$A$2:$A$100,0)) -> -1 | R51: =IF(L51=1,P51*Q51,"") -> 1 | S51: =IF(L51<>1,"Excluded",IF(Q51=0,"No direction",IF(R51>0,"Better",IF(R51<0,"Worse","No change")))) -> Better | U51: =C51&"|"&E51 -> F1_05|NLD
A52: 1 | B52: Spending | C52: F1_05 | D52: Poverty rate, % below poverty line of 60% | E52: CHE | F52: CHE | G52: 17 | H52: 16.4 | I52: 2023 | J52: 7 | K52: 7 | L52: 1 | M52: =IF(L52=1,COUNTIFS($C$2:$C$1090,C52,$L$2:$L$1090,1),"") -> 11 | N52: =IF(L52=1,1+COUNTIFS($C$2:$C$1090,C52,$L$2:$L$1090,1,$G$2:$G$1090,">"&G52),"") -> 6 | O52: =IF(L52=1,1+COUNTIFS($C$2:$C$1090,C52,$L$2:$L$1090,1,$H$2:$H$1090,">"&H52),"") -> 7 | P52: =IF(L52=1,N52-O52,"") -> -1 | Q52: =INDEX(Directions!$D$2:$D$100,MATCH(C52,Directions!$A$2:$A$100,0)) -> -1 | R52: =IF(L52=1,P52*Q52,"") -> 1 | S52: =IF(L52<>1,"Excluded",IF(Q52=0,"No direction",IF(R52>0,"Better",IF(R52<0,"Worse","No change")))) -> Better | U52: =C52&"|"&E52 -> F1_05|CHE
A53: 1 | B53: Spending | C53: F1_05 | D53: Poverty rate, % below poverty line of 60% | E53: DNK | F53: Denmark | G53: 12 | H53: 12.9 | I53: 2022 | J53: 11 | K53: 11 | L53: 1 | M53: =IF(L53=1,COUNTIFS($C$2:$C$1090,C53,$L$2:$L$1090,1),"") -> 11 | N53: =IF(L53=1,1+COUNTIFS($C$2:$C$1090,C53,$L$2:$L$1090,1,$G$2:$G$1090,">"&G53),"") -> 11 | O53: =IF(L53=1,1+COUNTIFS($C$2:$C$1090,C53,$L$2:$L$1090,1,$H$2:$H$1090,">"&H53),"") -> 11 | P53: =IF(L53=1,N53-O53,"") -> 0 | Q53: =INDEX(Directions!$D$2:$D$100,MATCH(C53,Directions!$A$2:$A$100,0)) -> -1 | R53: =IF(L53=1,P53*Q53,"") -> 0 | S53: =IF(L53<>1,"Excluded",IF(Q53=0,"No direction",IF(R53>0,"Better",IF(R53<0,"Worse","No change")))) -> No change | U53: =C53&"|"&E53 -> F1_05|DNK
A54: 1 | B54: Spending | C54: F1_05 | D54: Poverty rate, % below poverty line of 60% | E54: CAN | F54: Canada | G54: 21 | H54: 18.8 | I54: 2023 | J54: 3 | K54: 4 | L54: 1 | M54: =IF(L54=1,COUNTIFS($C$2:$C$1090,C54,$L$2:$L$1090,1),"") -> 11 | N54: =IF(L54=1,1+COUNTIFS($C$2:$C$1090,C54,$L$2:$L$1090,1,$G$2:$G$1090,">"&G54),"") -> 3 | O54: =IF(L54=1,1+COUNTIFS($C$2:$C$1090,C54,$L$2:$L$1090,1,$H$2:$H$1090,">"&H54),"") -> 4 | P54: =IF(L54=1,N54-O54,"") -> -1 | Q54: =INDEX(Directions!$D$2:$D$100,MATCH(C54,Directions!$A$2:$A$100,0)) -> -1 | R54: =IF(L54=1,P54*Q54,"") -> 1 | S54: =IF(L54<>1,"Excluded",IF(Q54=0,"No direction",IF(R54>0,"Better",IF(R54<0,"Worse","No change")))) -> Better | U54: =C54&"|"&E54 -> F1_05|CAN
A55: 1 | B55: Spending | C55: F1_05 | D55: Poverty rate, % below poverty line of 60% | E55: JPN | F55: Japan | G55: 22 | H55: 21.3 | I55: 2021 | J55: 2 | K55: 2 | L55: 1 | M55: =IF(L55=1,COUNTIFS($C$2:$C$1090,C55,$L$2:$L$1090,1),"") -> 11 | N55: =IF(L55=1,1+COUNTIFS($C$2:$C$1090,C55,$L$2:$L$1090,1,$G$2:$G$1090,">"&G55),"") -> 2 | O55: =IF(L55=1,1+COUNTIFS($C$2:$C$1090,C55,$L$2:$L$1090,1,$H$2:$H$1090,">"&H55),"") -> 2 | P55: =IF(L55=1,N55-O55,"") -> 0 | Q55: =INDEX(Directions!$D$2:$D$100,MATCH(C55,Directions!$A$2:$A$100,0)) -> -1 | R55: =IF(L55=1,P55*Q55,"") -> 0 | S55: =IF(L55<>1,"Excluded",IF(Q55=0,"No direction",IF(R55>0,"Better",IF(R55<0,"Worse","No change")))) -> No change | U55: =C55&"|"&E55 -> F1_05|JPN
A56: 1 | B56: Spending | C56: F1_05 | D56: Poverty rate, % below poverty line of 60% | E56: AUS | F56: Australia | G56: 20 | H56: 20.4 | I56: 2020 | J56: 4 | K56: 3 | L56: 1 | M56: =IF(L56=1,COUNTIFS($C$2:$C$1090,C56,$L$2:$L$1090,1),"") -> 11 | N56: =IF(L56=1,1+COUNTIFS($C$2:$C$1090,C56,$L$2:$L$1090,1,$G$2:$G$1090,">"&G56),"") -> 4 | O56: =IF(L56=1,1+COUNTIFS($C$2:$C$1090,C56,$L$2:$L$1090,1,$H$2:$H$1090,">"&H56),"") -> 3 | P56: =IF(L56=1,N56-O56,"") -> 1 | Q56: =INDEX(Directions!$D$2:$D$100,MATCH(C56,Directions!$A$2:$A$100,0)) -> -1 | R56: =IF(L56=1,P56*Q56,"") -> -1 | S56: =IF(L56<>1,"Excluded",IF(Q56=0,"No direction",IF(R56>0,"Better",IF(R56<0,"Worse","No change")))) -> Worse | U56: =C56&"|"&E56 -> F1_05|AUS
A57: 1 | B57: Spending | C57: F1_06 | D57: Total spending on health, % of total national GDP | E57: USA | F57: US | G57: 17.8 | H57: 16.69 | I57: 2023 | J57: 1 | K57: 1 | L57: 1 | M57: =IF(L57=1,COUNTIFS($C$2:$C$1090,C57,$L$2:$L$1090,1),"") -> 11 | N57: =IF(L57=1,1+COUNTIFS($C$2:$C$1090,C57,$L$2:$L$1090,1,$G$2:$G$1090,">"&G57),"") -> 1 | O57: =IF(L57=1,1+COUNTIFS($C$2:$C$1090,C57,$L$2:$L$1090,1,$H$2:$H$1090,">"&H57),"") -> 1 | P57: =IF(L57=1,N57-O57,"") -> 0 | Q57: =INDEX(Directions!$D$2:$D$100,MATCH(C57,Directions!$A$2:$A$100,0)) -> 0 | R57: =IF(L57=1,P57*Q57,"") -> 0 | S57: =IF(L57<>1,"Excluded",IF(Q57=0,"No direction",IF(R57>0,"Better",IF(R57<0,"Worse","No change")))) -> No direction | U57: =C57&"|"&E57 -> F1_06|USA
... A72: 1 | B72: Spending | C72: F1_07 | D72: Public spending on health, % of total national GDP | E72: FRA | F72: France | G72: 8.7 | H72: 7.89 | I72: 2024 | J72: 5 | K72: 7 | L72: 1 | M72: =IF(L72=1,COUNTIFS($C$2:$C$1090,C72,$L$2:$L$1090,1),"") -> 9 | N72: =IF(L72=1,1+COUNTIFS($C$2:$C$1090,C72,$L$2:$L$1090,1,$G$2:$G$1090,">"&G72),"") -> 3 | O72: =IF(L72=1,1+COUNTIFS($C$2:$C$1090,C72,$L$2:$L$1090,1,$H$2:$H$1090,">"&H72),"") -> 7 | P72: =IF(L72=1,N72-O72,"") -> -4 | Q72: =INDEX(Directions!$D$2:$D$100,MATCH(C72,Directions!$A$2:$A$100,0)) -> 0 | R72: =IF(L72=1,P72*Q72,"") -> 0 | S72: =IF(L72<>1,"Excluded",IF(Q72=0,"No direction",IF(R72>0,"Better",IF(R72<0,"Worse","No change")))) -> No direction | U72: =C72&"|"&E72 -> F1_07|FRA
A73: 1 | B73: Spending | C73: F1_07 | D73: Public spending on health, % of total national GDP | E73: NLD | F73: NLD | G73: 9.5 | H73: 6.72 | I73: 2023 | J73: 2 | K73: 10 | L73: 0 | M73: =IF(L73=1,COUNTIFS($C$2:$C$1090,C73,$L$2:$L$1090,1),"") | N73: =IF(L73=1,1+COUNTIFS($C$2:$C$1090,C73,$L$2:$L$1090,1,$G$2:$G$1090,">"&G73),"") | O73: =IF(L73=1,1+COUNTIFS($C$2:$C$1090,C73,$L$2:$L$1090,1,$H$2:$H$1090,">"&H73),"") | P73: =IF(L73=1,N73-O73,"") | Q73: =INDEX(Directions!$D$2:$D$100,MATCH(C73,Directions!$A$2:$A$100,0)) -> 0 | R73: =IF(L73=1,P73*Q73,"") | S73: =IF(L73<>1,"Excluded",IF(Q73=0,"No direction",IF(R73>0,"Better",IF(R73<0,"Worse","No change")))) -> Excluded | T73: Excluded: Mandatory insurance now classed as private in WHO GHED | U73: =C73&"|"&E73 -> F1_07|NLD
A74: 1 | B74: Spending | C74: F1_07 | D74: Public spending on health, % of total national GDP | E74: CHE | F74: CHE | G74: 7.7 | H74: 3.87 | I74: 2023 | J74: 8 | K74: 11 | L74: 0 | M74: =IF(L74=1,COUNTIFS($C$2:$C$1090,C74,$L$2:$L$1090,1),"") | N74: =IF(L74=1,1+COUNTIFS($C$2:$C$1090,C74,$L$2:$L$1090,1,$G$2:$G$1090,">"&G74),"") | O74: =IF(L74=1,1+COUNTIFS($C$2:$C$1090,C74,$L$2:$L$1090,1,$H$2:$H$1090,">"&H74),"") | P74: =IF(L74=1,N74-O74,"") | Q74: =INDEX(Directions!$D$2:$D$100,MATCH(C74,Directions!$A$2:$A$100,0)) -> 0 | R74: =IF(L74=1,P74*Q74,"") | S74: =IF(L74<>1,"Excluded",IF(Q74=0,"No direction",IF(R74>0,"Better",IF(R74<0,"Worse","No change")))) -> Excluded | T74: Excluded: Mandatory insurance now classed as private in WHO GHED | U74: =C74&"|"&E74 -> F1_07|CHE
...

Sheet Performance_Matrix
A1: Relative performance change, 2018 → 2026 (positions gained among comparable countries)
A2: Green = better relative standing; red = worse; 0 = same position; – = not comparable. Indicators with a desirable direction only (see Directions). Example: +2 for a mortality row means the country moved 2 places toward the low-mortality end.
A4: Indicator ID | B4: Domain | C4: Indicator | D4: US | E4: UK | F4: Germany | G4: Sweden | H4: France | I4: NLD | J4: CHE | K4: Denmark | L4: Canada | M4: Japan | N4: Australia
A5: F1_05 | B5: Spending | C5: Poverty rate, % below poverty line of 60% | D5: =IFERROR(IF(INDEX(Rank_Changes!$R$2:$R$1090,MATCH($A5&"|"&"USA",Rank_Changes!$U$2:$U$1090,0))="","–",INDEX(Rank_Changes!$R$2:$R$1090,MATCH($A5&"|"&"USA",Rank_Changes!$U$2:$U$1090,0))),"–") -> 0 | E5: =IFERROR(IF(INDEX(Rank_Changes!$R$2:$R$1090,MATCH($A5&"|"&"GBR",Rank_Changes!$U$2:$U$1090,0))="","–",INDEX(Rank_Changes!$R$2:$R$1090,MATCH($A5&"|"&"GBR",Rank_Changes!$U$2:$U$1090,0))),"–") -> 0 | F5: =IFERROR(IF(INDEX(Rank_Changes!$R$2:$R$1090,MATCH($A5&"|"&"DEU",Rank_Changes!$U$2:$U$1090,0))="","–",INDEX(Rank_Changes!$R$2:$R$1090,MATCH($A5&"|"&"DEU",Rank_Changes!$U$2:$U$1090,0))),"–") -> -2 | G5: =IFERROR(IF(INDEX(Rank_Changes!$R$2:$R$1090,MATCH($A5&"|"&"SWE",Rank_Changes!$U$2:$U$1090,0))="","–",INDEX(Rank_Changes!$R$2:$R$1090,MATCH($A5&"|"&"SWE",Rank_Changes!$U$2:$U$1090,0))),"–") -> 2 | H5: =IFERROR(IF(INDEX(Rank_Changes!$R$2:$R$1090,MATCH($A5&"|"&"FRA",Rank_Changes!$U$2:$U$1090,0))="","–",INDEX(Rank_Changes!$R$2:$R$1090,MATCH($A5&"|"&"FRA",Rank_Changes!$U$2:$U$1090,0))),"–") -> 0 | I5: =IFERROR(IF(INDEX(Rank_Changes!$R$2:$R$1090,MATCH($A5&"|"&"NLD",Rank_Changes!$U$2:$U$1090,0))="","–",INDEX(Rank_Changes!$R$2:$R$1090,MATCH($A5&"|"&"NLD",Rank_Changes!$U$2:$U$1090,0))),"–") -> 1 | J5: =IFERROR(IF(INDEX(Rank_Changes!$R$2:$R$1090,MATCH($A5&"|"&"CHE",Rank_Changes!$U$2:$U$1090,0))="","–",INDEX(Rank_Changes!$R$2:$R$1090,MATCH($A5&"|"&"CHE",Rank_Changes!$U$2:$U$1090,0))),"–") -> 1 | K5: =IFERROR(IF(INDEX(Rank_Changes!$R$2:$R$1090,MATCH($A5&"|"&"DNK",Rank_Changes!$U$2:$U$1090,0))="","–",INDEX(Rank_Changes!$R$2:$R$1090,MATCH($A5&"|"&"DNK",Rank_Changes!$U$2:$U$1090,0))),"–") -> 0 | L5: =IFERROR(IF(INDEX(Rank_Changes!$R$2:$R$1090,MATCH($A5&"|"&"CAN",Rank_Changes!$U$2:$U$1090,0))="","–",INDEX(Rank_Changes!$R$2:$R$1090,MATCH($A5&"|"&"CAN",Rank_Changes!$U$2:$U$1090,0))),"–") -> 1 | M5: =IFERROR(IF(INDEX(Rank_Changes!$R$2:$R$1090,MATCH($A5&"|"&"JPN",Rank_Changes!$U$2:$U$1090,0))="","–",INDEX(Rank_Changes!$R$2:$R$1090,MATCH($A5&"|"&"JPN",Rank_Changes!$U$2:$U$1090,0))),"–") -> 0 | N5: =IFERROR(IF(INDEX(Rank_Changes!$R$2:$R$1090,MATCH($A5&"|"&"AUS",Rank_Changes!$U$2:$U$1090,0))="","–",INDEX(Rank_Changes!$R$2:$R$1090,MATCH($A5&"|"&"AUS",Rank_Changes!$U$2:$U$1090,0))),"–") -> -1
A6: F1_17 | B6: Spending | C6: Population with health care coverage, % | D6: =IFERROR(IF(INDEX(Rank_Changes!$R$2:$R$1090,MATCH($A6&"|"&"USA",Rank_Changes!$U$2:$U$1090,0))="","–",INDEX(Rank_Changes!$R$2:$R$1090,MATCH($A6&"|"&"USA",Rank_Changes!$U$2:$U$1090,0))),"–") -> 0 | E6: =IFERROR(IF(INDEX(Rank_Changes!$R$2:$R$1090,MATCH($A6&"|"&"GBR",Rank_Changes!$U$2:$U$1090,0))="","–",INDEX(Rank_Changes!$R$2:$R$1090,MATCH($A6&"|"&"GBR",Rank_Changes!$U$2:$U$1090,0))),"–") -> 0 | F6: =IFERROR(IF(INDEX(Rank_Changes!$R$2:$R$1090,MATCH($A6&"|"&"DEU",Rank_Changes!$U$2:$U$1090,0))="","–",INDEX(Rank_Changes!$R$2:$R$1090,MATCH($A6&"|"&"DEU",Rank_Changes!$U$2:$U$1090,0))),"–") -> 2 | G6: =IFERROR(IF(INDEX(Rank_Changes!$R$2:$R$1090,MATCH($A6&"|"&"SWE",Rank_Changes!$U$2:$U$1090,0))="","–",INDEX(Rank_Changes!$R$2:$R$1090,MATCH($A6&"|"&"SWE",Rank_Changes!$U$2:$U$1090,0))),"–") -> 0 | H6: =IFERROR(IF(INDEX(Rank_Changes!$R$2:$R$1090,MATCH($A6&"|"&"FRA",Rank_Changes!$U$2:$U$1090,0))="","–",INDEX(Rank_Changes!$R$2:$R$1090,MATCH($A6&"|"&"FRA",Rank_Changes!$U$2:$U$1090,0))),"–") -> 0 | I6: =IFERROR(IF(INDEX(Rank_Changes!$R$2:$R$1090,MATCH($A6&"|"&"NLD",Rank_Changes!$U$2:$U$1090,0))="","–",INDEX(Rank_Changes!$R$2:$R$1090,MATCH($A6&"|"&"NLD",Rank_Changes!$U$2:$U$1090,0))),"–") -> -2 | J6: =IFERROR(IF(INDEX(Rank_Changes!$R$2:$R$1090,MATCH($A6&"|"&"CHE",Rank_Changes!$U$2:$U$1090,0))="","–",INDEX(Rank_Changes!$R$2:$R$1090,MATCH($A6&"|"&"CHE",Rank_Changes!$U$2:$U$1090,0))),"–") -> 0 | K6: =IFERROR(IF(INDEX(Rank_Changes!$R$2:$R$1090,MATCH($A6&"|"&"DNK",Rank_Changes!$U$2:$U$1090,0))="","–",INDEX(Rank_Changes!$R$2:$R$1090,MATCH($A6&"|"&"DNK",Rank_Changes!$U$2:$U$1090,0))),"–") -> 0 | L6: =IFERROR(IF(INDEX(Rank_Changes!$R$2:$R$1090,MATCH($A6&"|"&"CAN",Rank_Changes!$U$2:$U$1090,0))="","–",INDEX(Rank_Changes!$R$2:$R$1090,MATCH($A6&"|"&"CAN",Rank_Changes!$U$2:$U$1090,0))),"–") -> 0 | M6: =IFERROR(IF(INDEX(Rank_Changes!$R$2:$R$1090,MATCH($A6&"|"&"JPN",Rank_Changes!$U$2:$U$1090,0))="","–",INDEX(Rank_Changes!$R$2:$R$1090,MATCH($A6&"|"&"JPN",Rank_Changes!$U$2:$U$1090,0))),"–") -> 0 | N6: =IFERROR(IF(INDEX(Rank_Changes!$R$2:$R$1090,MATCH($A6&"|"&"AUS",Rank_Changes!$U$2:$U$1090,0))="","–",INDEX(Rank_Changes!$R$2:$R$1090,MATCH($A6&"|"&"AUS",Rank_Changes!$U$2:$U$1090,0))),"–") -> 0
